2024-10-29 01:34:54 - INFO - __main__ - Initializing training script
2024-10-29 01:34:54 - INFO - __main__ - Loading dataset...
2024-10-29 01:34:54 - INFO - __main__ - Loading model and tokenizer...
Traceback (most recent call last):
  File "/root/miniconda3/envs/pytorch/lib/python3.10/site-packages/urllib3/connection.py", line 199, in _new_conn
    sock = connection.create_connection(
  File "/root/miniconda3/envs/pytorch/lib/python3.10/site-packages/urllib3/util/connection.py", line 85, in create_connection
    raise err
  File "/root/miniconda3/envs/pytorch/lib/python3.10/site-packages/urllib3/util/connection.py", line 73, in create_connection
    sock.connect(sa)
TimeoutError: timed out

The above exception was the direct cause of the following exception:

Traceback (most recent call last):
  File "/root/miniconda3/envs/pytorch/lib/python3.10/site-packages/urllib3/connectionpool.py", line 789, in urlopen
    response = self._make_request(
  File "/root/miniconda3/envs/pytorch/lib/python3.10/site-packages/urllib3/connectionpool.py", line 490, in _make_request
    raise new_e
  File "/root/miniconda3/envs/pytorch/lib/python3.10/site-packages/urllib3/connectionpool.py", line 466, in _make_request
    self._validate_conn(conn)
  File "/root/miniconda3/envs/pytorch/lib/python3.10/site-packages/urllib3/connectionpool.py", line 1095, in _validate_conn
    conn.connect()
  File "/root/miniconda3/envs/pytorch/lib/python3.10/site-packages/urllib3/connection.py", line 693, in connect
    self.sock = sock = self._new_conn()
  File "/root/miniconda3/envs/pytorch/lib/python3.10/site-packages/urllib3/connection.py", line 208, in _new_conn
    raise ConnectTimeoutError(
urllib3.exceptions.ConnectTimeoutError: (<urllib3.connection.HTTPSConnection object at 0x7f5712640eb0>, 'Connection to huggingface.co timed out. (connect timeout=10)')

The above exception was the direct cause of the following exception:

Traceback (most recent call last):
  File "/root/miniconda3/envs/pytorch/lib/python3.10/site-packages/requests/adapters.py", line 667, in send
    resp = conn.urlopen(
  File "/root/miniconda3/envs/pytorch/lib/python3.10/site-packages/urllib3/connectionpool.py", line 843, in urlopen
    retries = retries.increment(
  File "/root/miniconda3/envs/pytorch/lib/python3.10/site-packages/urllib3/util/retry.py", line 519, in increment
    raise MaxRetryError(_pool, url, reason) from reason  # type: ignore[arg-type]
urllib3.exceptions.MaxRetryError: HTTPSConnectionPool(host='huggingface.co', port=443): Max retries exceeded with url: /roberta-base/resolve/main/config.json (Caused by ConnectTimeoutError(<urllib3.connection.HTTPSConnection object at 0x7f5712640eb0>, 'Connection to huggingface.co timed out. (connect timeout=10)'))

During handling of the above exception, another exception occurred:

Traceback (most recent call last):
  File "/root/miniconda3/envs/pytorch/lib/python3.10/site-packages/huggingface_hub/file_download.py", line 1376, in _get_metadata_or_catch_error
    metadata = get_hf_file_metadata(
  File "/root/miniconda3/envs/pytorch/lib/python3.10/site-packages/huggingface_hub/utils/_validators.py", line 114, in _inner_fn
    return fn(*args, **kwargs)
  File "/root/miniconda3/envs/pytorch/lib/python3.10/site-packages/huggingface_hub/file_download.py", line 1296, in get_hf_file_metadata
    r = _request_wrapper(
  File "/root/miniconda3/envs/pytorch/lib/python3.10/site-packages/huggingface_hub/file_download.py", line 277, in _request_wrapper
    response = _request_wrapper(
  File "/root/miniconda3/envs/pytorch/lib/python3.10/site-packages/huggingface_hub/file_download.py", line 300, in _request_wrapper
    response = get_session().request(method=method, url=url, **params)
  File "/root/miniconda3/envs/pytorch/lib/python3.10/site-packages/requests/sessions.py", line 589, in request
    resp = self.send(prep, **send_kwargs)
  File "/root/miniconda3/envs/pytorch/lib/python3.10/site-packages/requests/sessions.py", line 703, in send
    r = adapter.send(request, **kwargs)
  File "/root/miniconda3/envs/pytorch/lib/python3.10/site-packages/huggingface_hub/utils/_http.py", line 93, in send
    return super().send(request, *args, **kwargs)
  File "/root/miniconda3/envs/pytorch/lib/python3.10/site-packages/requests/adapters.py", line 688, in send
    raise ConnectTimeout(e, request=request)
requests.exceptions.ConnectTimeout: (MaxRetryError("HTTPSConnectionPool(host='huggingface.co', port=443): Max retries exceeded with url: /roberta-base/resolve/main/config.json (Caused by ConnectTimeoutError(<urllib3.connection.HTTPSConnection object at 0x7f5712640eb0>, 'Connection to huggingface.co timed out. (connect timeout=10)'))"), '(Request ID: cafe451a-dcf8-4c85-b9dd-f02109dc1d7f)')

The above exception was the direct cause of the following exception:

Traceback (most recent call last):
  File "/root/miniconda3/envs/pytorch/lib/python3.10/site-packages/transformers/utils/hub.py", line 403, in cached_file
    resolved_file = hf_hub_download(
  File "/root/miniconda3/envs/pytorch/lib/python3.10/site-packages/huggingface_hub/utils/_validators.py", line 114, in _inner_fn
    return fn(*args, **kwargs)
  File "/root/miniconda3/envs/pytorch/lib/python3.10/site-packages/huggingface_hub/file_download.py", line 862, in hf_hub_download
    return _hf_hub_download_to_cache_dir(
  File "/root/miniconda3/envs/pytorch/lib/python3.10/site-packages/huggingface_hub/file_download.py", line 969, in _hf_hub_download_to_cache_dir
    _raise_on_head_call_error(head_call_error, force_download, local_files_only)
  File "/root/miniconda3/envs/pytorch/lib/python3.10/site-packages/huggingface_hub/file_download.py", line 1487, in _raise_on_head_call_error
    raise LocalEntryNotFoundError(
huggingface_hub.errors.LocalEntryNotFoundError: An error happened while trying to locate the file on the Hub and we cannot find the requested files in the local cache. Please check your connection and try again or make sure your Internet connection is on.

The above exception was the direct cause of the following exception:

Traceback (most recent call last):
  File "/root/HW2/task2/train.py", line 68, in <module>
    config = AutoConfig.from_pretrained(model_args.model_name_or_path, num_labels=2)  # 根据数据集调整 num_labels
  File "/root/miniconda3/envs/pytorch/lib/python3.10/site-packages/transformers/models/auto/configuration_auto.py", line 1017, in from_pretrained
    config_dict, unused_kwargs = PretrainedConfig.get_config_dict(pretrained_model_name_or_path, **kwargs)
  File "/root/miniconda3/envs/pytorch/lib/python3.10/site-packages/transformers/configuration_utils.py", line 574, in get_config_dict
    config_dict, kwargs = cls._get_config_dict(pretrained_model_name_or_path, **kwargs)
  File "/root/miniconda3/envs/pytorch/lib/python3.10/site-packages/transformers/configuration_utils.py", line 633, in _get_config_dict
    resolved_config_file = cached_file(
  File "/root/miniconda3/envs/pytorch/lib/python3.10/site-packages/transformers/utils/hub.py", line 446, in cached_file
    raise EnvironmentError(
OSError: We couldn't connect to 'https://huggingface.co' to load this file, couldn't find it in the cached files and it looks like roberta-base is not the path to a directory containing a file named config.json.
Checkout your internet connection or see how to run the library in offline mode at 'https://huggingface.co/docs/transformers/installation#offline-mode'.
