2024-10-29 01:15:59 - INFO - __main__ - Initializing training script
2024-10-29 01:15:59 - INFO - __main__ - Loading dataset...
2024-10-29 01:15:59 - INFO - __main__ - Loading model and tokenizer...
D:\Anaconda\envs\pytorch\lib\site-packages\huggingface_hub\file_download.py:1132: FutureWarning: `resume_download` is deprecated and will be removed in version 1.0.0. Downloads always resume when possible. If you want to force a new download, use `force_download=True`.
  warnings.warn(
model.safetensors:  59%|█████████████████████████████████████████▊                             | 294M/499M [03:00<11:59, 285kB/s]Error while downloading from https://cdn-lfs.hf.co/roberta-base/5bde1d28afb363d0103324efeb5afc8b2b397fe5e04beabb9b1ef355255ade81?response-content-disposition=inline%3B+filename*%3DUTF-8%27%27model.safetensors%3B+filename%3D%22model.safetensors%22%3B&Expires=1730394776&Policy=eyJTdGF0ZW1lbnQiOlt7IkNvbmRpdGlvbiI6eyJEYXRlTGVzc1RoYW4iOnsiQVdTOkVwb2NoVGltZSI6MTczMDM5NDc3Nn19LCJSZXNvdXJjZSI6Imh0dHBzOi8vY2RuLWxmcy5oZi5jby9yb2JlcnRhLWJhc2UvNWJkZTFkMjhhZmIzNjNkMDEwMzMyNGVmZWI1YWZjOGIyYjM5N2ZlNWUwNGJlYWJiOWIxZWYzNTUyNTVhZGU4MT9yZXNwb25zZS1jb250ZW50LWRpc3Bvc2l0aW9uPSoifV19&Signature=aDWL256NkJppeAuH4Cr37Lwj44inPSxSSMJ-yDAbdt1VIEQmvWrGXeidKt7dc9Tw7VGg4EKAGyH9c-OjF41t8kfCEGeTtjuoLXf0W61fYE2AQ8Kz6TVtRDREE674cNl79bD0f4d7B45PCxTs%7E0irY1Fu2zfsx4qSSxb7wAZ88MFru1age4tJFneVxq7nPmuFMCr2NfYV5K81g39IFDXsiy%7EZqS4eqINyhYjbeWmhzdU-RHir8vlneDZPBM8SXXo2ZMIy5E%7EdVI5t7tnRidpQfQQBB4JxkSiVblBk--LRu65CFvmgsiL--PGtIcnjbOhAj5HcjXdpttshIRC7mRo7KQ__&Key-Pair-Id=K3RPWS32NSSJCE: HTTPSConnectionPool(host='cdn-lfs.hf.co', port=443): Read timed out.
Trying to resume download...
2024-10-29 01:19:34 - WARNING - huggingface_hub.file_download - Error while downloading from https://cdn-lfs.hf.co/roberta-base/5bde1d28afb363d0103324efeb5afc8b2b397fe5e04beabb9b1ef355255ade81?response-content-disposition=inline%3B+filename*%3DUTF-8%27%27model.safetensors%3B+filename%3D%22model.safetensors%22%3B&Expires=1730394776&Policy=eyJTdGF0ZW1lbnQiOlt7IkNvbmRpdGlvbiI6eyJEYXRlTGVzc1RoYW4iOnsiQVdTOkVwb2NoVGltZSI6MTczMDM5NDc3Nn19LCJSZXNvdXJjZSI6Imh0dHBzOi8vY2RuLWxmcy5oZi5jby9yb2JlcnRhLWJhc2UvNWJkZTFkMjhhZmIzNjNkMDEwMzMyNGVmZWI1YWZjOGIyYjM5N2ZlNWUwNGJlYWJiOWIxZWYzNTUyNTVhZGU4MT9yZXNwb25zZS1jb250ZW50LWRpc3Bvc2l0aW9uPSoifV19&Signature=aDWL256NkJppeAuH4Cr37Lwj44inPSxSSMJ-yDAbdt1VIEQmvWrGXeidKt7dc9Tw7VGg4EKAGyH9c-OjF41t8kfCEGeTtjuoLXf0W61fYE2AQ8Kz6TVtRDREE674cNl79bD0f4d7B45PCxTs%7E0irY1Fu2zfsx4qSSxb7wAZ88MFru1age4tJFneVxq7nPmuFMCr2NfYV5K81g39IFDXsiy%7EZqS4eqINyhYjbeWmhzdU-RHir8vlneDZPBM8SXXo2ZMIy5E%7EdVI5t7tnRidpQfQQBB4JxkSiVblBk--LRu65CFvmgsiL--PGtIcnjbOhAj5HcjXdpttshIRC7mRo7KQ__&Key-Pair-Id=K3RPWS32NSSJCE: HTTPSConnectionPool(host='cdn-lfs.hf.co', port=443): Read timed out.
Trying to resume download...
                                                                                                                                 Error while downloading from https://cdn-lfs.hf.co/roberta-base/5bde1d28afb363d0103324efeb5afc8b2b397fe5e04beabb9b1ef355255ade81?response-content-disposition=inline%3B+filename*%3DUTF-8%27%27model.safetensors%3B+filename%3D%22model.safetensors%22%3B&Expires=1730394776&Policy=eyJTdGF0ZW1lbnQiOlt7IkNvbmRpdGlvbiI6eyJEYXRlTGVzc1RoYW4iOnsiQVdTOkVwb2NoVGltZSI6MTczMDM5NDc3Nn19LCJSZXNvdXJjZSI6Imh0dHBzOi8vY2RuLWxmcy5oZi5jby9yb2JlcnRhLWJhc2UvNWJkZTFkMjhhZmIzNjNkMDEwMzMyNGVmZWI1YWZjOGIyYjM5N2ZlNWUwNGJlYWJiOWIxZWYzNTUyNTVhZGU4MT9yZXNwb25zZS1jb250ZW50LWRpc3Bvc2l0aW9uPSoifV19&Signature=aDWL256NkJppeAuH4Cr37Lwj44inPSxSSMJ-yDAbdt1VIEQmvWrGXeidKt7dc9Tw7VGg4EKAGyH9c-OjF41t8kfCEGeTtjuoLXf0W61fYE2AQ8Kz6TVtRDREE674cNl79bD0f4d7B45PCxTs%7E0irY1Fu2zfsx4qSSxb7wAZ88MFru1age4tJFneVxq7nPmuFMCr2NfYV5K81g39IFDXsiy%7EZqS4eqINyhYjbeWmhzdU-RHir8vlneDZPBM8SXXo2ZMIy5E%7EdVI5t7tnRidpQfQQBB4JxkSiVblBk--LRu65CFvmgsiL--PGtIcnjbOhAj5HcjXdpttshIRC7mRo7KQ__&Key-Pair-Id=K3RPWS32NSSJCE: The operation did not complete (read) (_ssl.c:2639)
Trying to resume download...████████████████████████████████████████████████████████████▋     | 461M/499M [00:26<00:03, 12.4MB/s]
2024-10-29 01:20:46 - WARNING - huggingface_hub.file_download - Error while downloading from https://cdn-lfs.hf.co/roberta-base/5bde1d28afb363d0103324efeb5afc8b2b397fe5e04beabb9b1ef355255ade81?response-content-disposition=inline%3B+filename*%3DUTF-8%27%27model.safetensors%3B+filename%3D%22model.safetensors%22%3B&Expires=1730394776&Policy=eyJTdGF0ZW1lbnQiOlt7IkNvbmRpdGlvbiI6eyJEYXRlTGVzc1RoYW4iOnsiQVdTOkVwb2NoVGltZSI6MTczMDM5NDc3Nn19LCJSZXNvdXJjZSI6Imh0dHBzOi8vY2RuLWxmcy5oZi5jby9yb2JlcnRhLWJhc2UvNWJkZTFkMjhhZmIzNjNkMDEwMzMyNGVmZWI1YWZjOGIyYjM5N2ZlNWUwNGJlYWJiOWIxZWYzNTUyNTVhZGU4MT9yZXNwb25zZS1jb250ZW50LWRpc3Bvc2l0aW9uPSoifV19&Signature=aDWL256NkJppeAuH4Cr37Lwj44inPSxSSMJ-yDAbdt1VIEQmvWrGXeidKt7dc9Tw7VGg4EKAGyH9c-OjF41t8kfCEGeTtjuoLXf0W61fYE2AQ8Kz6TVtRDREE674cNl79bD0f4d7B45PCxTs%7E0irY1Fu2zfsx4qSSxb7wAZ88MFru1age4tJFneVxq7nPmuFMCr2NfYV5K81g39IFDXsiy%7EZqS4eqINyhYjbeWmhzdU-RHir8vlneDZPBM8SXXo2ZMIy5E%7EdVI5t7tnRidpQfQQBB4JxkSiVblBk--LRu65CFvmgsiL--PGtIcnjbOhAj5HcjXdpttshIRC7mRo7KQ__&Key-Pair-Id=K3RPWS32NSSJCE: The operation did not complete (read) (_ssl.c:2639)
Trying to resume download...
                                                                                                                                 Traceback (most recent call last):
  File "D:\Anaconda\envs\pytorch\lib\site-packages\urllib3\response.py", line 748, in _error_catcher
    yieldetensors:  92%|████████████████████████████████████████████████████████████████████████▏     | 461M/499M [00:00<?, ?B/s]
  File "D:\Anaconda\envs\pytorch\lib\site-packages\urllib3\response.py", line 873, in _raw_read
    data = self._fp_read(amt, read1=read1) if not fp_closed else b""
  File "D:\Anaconda\envs\pytorch\lib\site-packages\urllib3\response.py", line 856, in _fp_read
    return self._fp.read(amt) if amt is not None else self._fp.read()
  File "D:\Anaconda\envs\pytorch\lib\http\client.py", line 459, in read
    n = self.readinto(b)
  File "D:\Anaconda\envs\pytorch\lib\http\client.py", line 503, in readinto
    n = self.fp.readinto(b)
  File "D:\Anaconda\envs\pytorch\lib\socket.py", line 669, in readinto
    return self._sock.recv_into(b)
  File "D:\Anaconda\envs\pytorch\lib\ssl.py", line 1274, in recv_into
    return self.read(nbytes, buffer)
  File "D:\Anaconda\envs\pytorch\lib\ssl.py", line 1132, in read
    return self._sslobj.read(len, buffer)
socket.timeout: The read operation timed out

The above exception was the direct cause of the following exception:

Traceback (most recent call last):
  File "D:\Anaconda\envs\pytorch\lib\site-packages\requests\models.py", line 820, in generate
    yield from self.raw.stream(chunk_size, decode_content=True)
  File "D:\Anaconda\envs\pytorch\lib\site-packages\urllib3\response.py", line 1060, in stream
    data = self.read(amt=amt, decode_content=decode_content)
  File "D:\Anaconda\envs\pytorch\lib\site-packages\urllib3\response.py", line 949, in read
    data = self._raw_read(amt)
  File "D:\Anaconda\envs\pytorch\lib\site-packages\urllib3\response.py", line 902, in _raw_read
    self._fp.close()
  File "D:\Anaconda\envs\pytorch\lib\contextlib.py", line 131, in __exit__
    self.gen.throw(type, value, traceback)
  File "D:\Anaconda\envs\pytorch\lib\site-packages\urllib3\response.py", line 753, in _error_catcher
    raise ReadTimeoutError(self._pool, None, "Read timed out.") from e  # type: ignore[arg-type]
urllib3.exceptions.ReadTimeoutError: HTTPSConnectionPool(host='cdn-lfs.hf.co', port=443): Read timed out.

During handling of the above exception, another exception occurred:

Traceback (most recent call last):
  File "D:\Anaconda\envs\pytorch\lib\site-packages\huggingface_hub\file_download.py", line 539, in http_get
    for chunk in r.iter_content(chunk_size=DOWNLOAD_CHUNK_SIZE):
  File "D:\Anaconda\envs\pytorch\lib\site-packages\requests\models.py", line 826, in generate
    raise ConnectionError(e)
requests.exceptions.ConnectionError: HTTPSConnectionPool(host='cdn-lfs.hf.co', port=443): Read timed out.

During handling of the above exception, another exception occurred:

Traceback (most recent call last):
  File "D:\Anaconda\envs\pytorch\lib\site-packages\urllib3\response.py", line 748, in _error_catcher
    yield
  File "D:\Anaconda\envs\pytorch\lib\site-packages\urllib3\response.py", line 873, in _raw_read
    data = self._fp_read(amt, read1=read1) if not fp_closed else b""
  File "D:\Anaconda\envs\pytorch\lib\site-packages\urllib3\response.py", line 856, in _fp_read
    return self._fp.read(amt) if amt is not None else self._fp.read()
  File "D:\Anaconda\envs\pytorch\lib\http\client.py", line 459, in read
    n = self.readinto(b)
  File "D:\Anaconda\envs\pytorch\lib\http\client.py", line 503, in readinto
    n = self.fp.readinto(b)
  File "D:\Anaconda\envs\pytorch\lib\socket.py", line 669, in readinto
    return self._sock.recv_into(b)
  File "D:\Anaconda\envs\pytorch\lib\ssl.py", line 1274, in recv_into
    return self.read(nbytes, buffer)
  File "D:\Anaconda\envs\pytorch\lib\ssl.py", line 1132, in read
    return self._sslobj.read(len, buffer)
ssl.SSLWantReadError: The operation did not complete (read) (_ssl.c:2639)

The above exception was the direct cause of the following exception:

Traceback (most recent call last):
  File "D:\Anaconda\envs\pytorch\lib\site-packages\requests\models.py", line 820, in generate
    yield from self.raw.stream(chunk_size, decode_content=True)
  File "D:\Anaconda\envs\pytorch\lib\site-packages\urllib3\response.py", line 1060, in stream
    data = self.read(amt=amt, decode_content=decode_content)
  File "D:\Anaconda\envs\pytorch\lib\site-packages\urllib3\response.py", line 949, in read
    data = self._raw_read(amt)
  File "D:\Anaconda\envs\pytorch\lib\site-packages\urllib3\response.py", line 902, in _raw_read
    self._fp.close()
  File "D:\Anaconda\envs\pytorch\lib\contextlib.py", line 131, in __exit__
    self.gen.throw(type, value, traceback)
  File "D:\Anaconda\envs\pytorch\lib\site-packages\urllib3\response.py", line 759, in _error_catcher
    raise SSLError(e) from e
urllib3.exceptions.SSLError: The operation did not complete (read) (_ssl.c:2639)

During handling of the above exception, another exception occurred:

Traceback (most recent call last):
  File "D:\Anaconda\envs\pytorch\lib\site-packages\huggingface_hub\file_download.py", line 539, in http_get
    for chunk in r.iter_content(chunk_size=DOWNLOAD_CHUNK_SIZE):
  File "D:\Anaconda\envs\pytorch\lib\site-packages\requests\models.py", line 828, in generate
    raise RequestsSSLError(e)
requests.exceptions.SSLError: The operation did not complete (read) (_ssl.c:2639)

During handling of the above exception, another exception occurred:

Traceback (most recent call last):
  File "train.py", line 69, in <module>
    model = AutoModelForSequenceClassification.from_pretrained(model_args.model_name_or_path, config=config)
  File "D:\Anaconda\envs\pytorch\lib\site-packages\transformers\models\auto\auto_factory.py", line 563, in from_pretrained
    return model_class.from_pretrained(
  File "D:\Anaconda\envs\pytorch\lib\site-packages\transformers\modeling_utils.py", line 3306, in from_pretrained
    resolved_archive_file = cached_file(pretrained_model_name_or_path, filename, **cached_file_kwargs)
  File "D:\Anaconda\envs\pytorch\lib\site-packages\transformers\utils\hub.py", line 398, in cached_file
    resolved_file = hf_hub_download(
  File "D:\Anaconda\envs\pytorch\lib\site-packages\huggingface_hub\utils\_validators.py", line 114, in _inner_fn
    return fn(*args, **kwargs)
  File "D:\Anaconda\envs\pytorch\lib\site-packages\huggingface_hub\file_download.py", line 1221, in hf_hub_download
    return _hf_hub_download_to_cache_dir(
  File "D:\Anaconda\envs\pytorch\lib\site-packages\huggingface_hub\file_download.py", line 1367, in _hf_hub_download_to_cache_dir
    _download_to_tmp_and_move(
  File "D:\Anaconda\envs\pytorch\lib\site-packages\huggingface_hub\file_download.py", line 1884, in _download_to_tmp_and_move
    http_get(
  File "D:\Anaconda\envs\pytorch\lib\site-packages\huggingface_hub\file_download.py", line 556, in http_get
    return http_get(
  File "D:\Anaconda\envs\pytorch\lib\site-packages\huggingface_hub\file_download.py", line 556, in http_get
    return http_get(
  File "D:\Anaconda\envs\pytorch\lib\site-packages\huggingface_hub\file_download.py", line 539, in http_get
    for chunk in r.iter_content(chunk_size=DOWNLOAD_CHUNK_SIZE):
  File "D:\Anaconda\envs\pytorch\lib\site-packages\requests\models.py", line 820, in generate
    yield from self.raw.stream(chunk_size, decode_content=True)
  File "D:\Anaconda\envs\pytorch\lib\site-packages\urllib3\response.py", line 1060, in stream
    data = self.read(amt=amt, decode_content=decode_content)
  File "D:\Anaconda\envs\pytorch\lib\site-packages\urllib3\response.py", line 949, in read
    data = self._raw_read(amt)
  File "D:\Anaconda\envs\pytorch\lib\site-packages\urllib3\response.py", line 873, in _raw_read
    data = self._fp_read(amt, read1=read1) if not fp_closed else b""
  File "D:\Anaconda\envs\pytorch\lib\site-packages\urllib3\response.py", line 856, in _fp_read
    return self._fp.read(amt) if amt is not None else self._fp.read()
  File "D:\Anaconda\envs\pytorch\lib\http\client.py", line 459, in read
    n = self.readinto(b)
  File "D:\Anaconda\envs\pytorch\lib\http\client.py", line 503, in readinto
    n = self.fp.readinto(b)
  File "D:\Anaconda\envs\pytorch\lib\socket.py", line 669, in readinto
    return self._sock.recv_into(b)
  File "D:\Anaconda\envs\pytorch\lib\ssl.py", line 1274, in recv_into
    return self.read(nbytes, buffer)
  File "D:\Anaconda\envs\pytorch\lib\ssl.py", line 1132, in read
    return self._sslobj.read(len, buffer)
KeyboardInterrupt
Traceback (most recent call last):
  File "D:\Anaconda\envs\pytorch\lib\site-packages\urllib3\response.py", line 748, in _error_catcher
    yield
  File "D:\Anaconda\envs\pytorch\lib\site-packages\urllib3\response.py", line 873, in _raw_read
    data = self._fp_read(amt, read1=read1) if not fp_closed else b""
  File "D:\Anaconda\envs\pytorch\lib\site-packages\urllib3\response.py", line 856, in _fp_read
    return self._fp.read(amt) if amt is not None else self._fp.read()
  File "D:\Anaconda\envs\pytorch\lib\http\client.py", line 459, in read
    n = self.readinto(b)
  File "D:\Anaconda\envs\pytorch\lib\http\client.py", line 503, in readinto
    n = self.fp.readinto(b)
  File "D:\Anaconda\envs\pytorch\lib\socket.py", line 669, in readinto
    return self._sock.recv_into(b)
  File "D:\Anaconda\envs\pytorch\lib\ssl.py", line 1274, in recv_into
    return self.read(nbytes, buffer)
  File "D:\Anaconda\envs\pytorch\lib\ssl.py", line 1132, in read
    return self._sslobj.read(len, buffer)
socket.timeout: The read operation timed out

The above exception was the direct cause of the following exception:

Traceback (most recent call last):
  File "D:\Anaconda\envs\pytorch\lib\site-packages\requests\models.py", line 820, in generate
    yield from self.raw.stream(chunk_size, decode_content=True)
  File "D:\Anaconda\envs\pytorch\lib\site-packages\urllib3\response.py", line 1060, in stream
    data = self.read(amt=amt, decode_content=decode_content)
  File "D:\Anaconda\envs\pytorch\lib\site-packages\urllib3\response.py", line 949, in read
    data = self._raw_read(amt)
  File "D:\Anaconda\envs\pytorch\lib\site-packages\urllib3\response.py", line 902, in _raw_read
    self._fp.close()
  File "D:\Anaconda\envs\pytorch\lib\contextlib.py", line 131, in __exit__
    self.gen.throw(type, value, traceback)
  File "D:\Anaconda\envs\pytorch\lib\site-packages\urllib3\response.py", line 753, in _error_catcher
    raise ReadTimeoutError(self._pool, None, "Read timed out.") from e  # type: ignore[arg-type]
urllib3.exceptions.ReadTimeoutError: HTTPSConnectionPool(host='cdn-lfs.hf.co', port=443): Read timed out.

During handling of the above exception, another exception occurred:

Traceback (most recent call last):
  File "D:\Anaconda\envs\pytorch\lib\site-packages\huggingface_hub\file_download.py", line 539, in http_get
    for chunk in r.iter_content(chunk_size=DOWNLOAD_CHUNK_SIZE):
  File "D:\Anaconda\envs\pytorch\lib\site-packages\requests\models.py", line 826, in generate
    raise ConnectionError(e)
requests.exceptions.ConnectionError: HTTPSConnectionPool(host='cdn-lfs.hf.co', port=443): Read timed out.

During handling of the above exception, another exception occurred:

Traceback (most recent call last):
  File "D:\Anaconda\envs\pytorch\lib\site-packages\urllib3\response.py", line 748, in _error_catcher
    yield
  File "D:\Anaconda\envs\pytorch\lib\site-packages\urllib3\response.py", line 873, in _raw_read
    data = self._fp_read(amt, read1=read1) if not fp_closed else b""
  File "D:\Anaconda\envs\pytorch\lib\site-packages\urllib3\response.py", line 856, in _fp_read
    return self._fp.read(amt) if amt is not None else self._fp.read()
  File "D:\Anaconda\envs\pytorch\lib\http\client.py", line 459, in read
    n = self.readinto(b)
  File "D:\Anaconda\envs\pytorch\lib\http\client.py", line 503, in readinto
    n = self.fp.readinto(b)
  File "D:\Anaconda\envs\pytorch\lib\socket.py", line 669, in readinto
    return self._sock.recv_into(b)
  File "D:\Anaconda\envs\pytorch\lib\ssl.py", line 1274, in recv_into
    return self.read(nbytes, buffer)
  File "D:\Anaconda\envs\pytorch\lib\ssl.py", line 1132, in read
    return self._sslobj.read(len, buffer)
ssl.SSLWantReadError: The operation did not complete (read) (_ssl.c:2639)

The above exception was the direct cause of the following exception:

Traceback (most recent call last):
  File "D:\Anaconda\envs\pytorch\lib\site-packages\requests\models.py", line 820, in generate
    yield from self.raw.stream(chunk_size, decode_content=True)
  File "D:\Anaconda\envs\pytorch\lib\site-packages\urllib3\response.py", line 1060, in stream
    data = self.read(amt=amt, decode_content=decode_content)
  File "D:\Anaconda\envs\pytorch\lib\site-packages\urllib3\response.py", line 949, in read
    data = self._raw_read(amt)
  File "D:\Anaconda\envs\pytorch\lib\site-packages\urllib3\response.py", line 902, in _raw_read
    self._fp.close()
  File "D:\Anaconda\envs\pytorch\lib\contextlib.py", line 131, in __exit__
    self.gen.throw(type, value, traceback)
  File "D:\Anaconda\envs\pytorch\lib\site-packages\urllib3\response.py", line 759, in _error_catcher
    raise SSLError(e) from e
urllib3.exceptions.SSLError: The operation did not complete (read) (_ssl.c:2639)

During handling of the above exception, another exception occurred:

Traceback (most recent call last):
  File "D:\Anaconda\envs\pytorch\lib\site-packages\huggingface_hub\file_download.py", line 539, in http_get
    for chunk in r.iter_content(chunk_size=DOWNLOAD_CHUNK_SIZE):
  File "D:\Anaconda\envs\pytorch\lib\site-packages\requests\models.py", line 828, in generate
    raise RequestsSSLError(e)
requests.exceptions.SSLError: The operation did not complete (read) (_ssl.c:2639)

During handling of the above exception, another exception occurred:

Traceback (most recent call last):
  File "train.py", line 69, in <module>
    model = AutoModelForSequenceClassification.from_pretrained(model_args.model_name_or_path, config=config)
  File "D:\Anaconda\envs\pytorch\lib\site-packages\transformers\models\auto\auto_factory.py", line 563, in from_pretrained
    return model_class.from_pretrained(
  File "D:\Anaconda\envs\pytorch\lib\site-packages\transformers\modeling_utils.py", line 3306, in from_pretrained
    resolved_archive_file = cached_file(pretrained_model_name_or_path, filename, **cached_file_kwargs)
  File "D:\Anaconda\envs\pytorch\lib\site-packages\transformers\utils\hub.py", line 398, in cached_file
    resolved_file = hf_hub_download(
  File "D:\Anaconda\envs\pytorch\lib\site-packages\huggingface_hub\utils\_validators.py", line 114, in _inner_fn
    return fn(*args, **kwargs)
  File "D:\Anaconda\envs\pytorch\lib\site-packages\huggingface_hub\file_download.py", line 1221, in hf_hub_download
    return _hf_hub_download_to_cache_dir(
  File "D:\Anaconda\envs\pytorch\lib\site-packages\huggingface_hub\file_download.py", line 1367, in _hf_hub_download_to_cache_dir
    _download_to_tmp_and_move(
  File "D:\Anaconda\envs\pytorch\lib\site-packages\huggingface_hub\file_download.py", line 1884, in _download_to_tmp_and_move
    http_get(
  File "D:\Anaconda\envs\pytorch\lib\site-packages\huggingface_hub\file_download.py", line 556, in http_get
    return http_get(
  File "D:\Anaconda\envs\pytorch\lib\site-packages\huggingface_hub\file_download.py", line 556, in http_get
    return http_get(
  File "D:\Anaconda\envs\pytorch\lib\site-packages\huggingface_hub\file_download.py", line 539, in http_get
    for chunk in r.iter_content(chunk_size=DOWNLOAD_CHUNK_SIZE):
  File "D:\Anaconda\envs\pytorch\lib\site-packages\requests\models.py", line 820, in generate
    yield from self.raw.stream(chunk_size, decode_content=True)
  File "D:\Anaconda\envs\pytorch\lib\site-packages\urllib3\response.py", line 1060, in stream
    data = self.read(amt=amt, decode_content=decode_content)
  File "D:\Anaconda\envs\pytorch\lib\site-packages\urllib3\response.py", line 949, in read
    data = self._raw_read(amt)
  File "D:\Anaconda\envs\pytorch\lib\site-packages\urllib3\response.py", line 873, in _raw_read
    data = self._fp_read(amt, read1=read1) if not fp_closed else b""
  File "D:\Anaconda\envs\pytorch\lib\site-packages\urllib3\response.py", line 856, in _fp_read
    return self._fp.read(amt) if amt is not None else self._fp.read()
  File "D:\Anaconda\envs\pytorch\lib\http\client.py", line 459, in read
    n = self.readinto(b)
  File "D:\Anaconda\envs\pytorch\lib\http\client.py", line 503, in readinto
    n = self.fp.readinto(b)
  File "D:\Anaconda\envs\pytorch\lib\socket.py", line 669, in readinto
    return self._sock.recv_into(b)
  File "D:\Anaconda\envs\pytorch\lib\ssl.py", line 1274, in recv_into
    return self.read(nbytes, buffer)
  File "D:\Anaconda\envs\pytorch\lib\ssl.py", line 1132, in read
    return self._sslobj.read(len, buffer)
KeyboardInterrupt
