2024-10-29 01:09:48 - INFO - __main__ - Initializing training script
2024-10-29 01:09:48 - INFO - __main__ - Loading dataset...
2024-10-29 01:09:48 - INFO - __main__ - Loading model and tokenizer...
D:\Anaconda\envs\pytorch\lib\site-packages\huggingface_hub\file_download.py:1132: FutureWarning: `resume_download` is deprecated and will be removed in version 1.0.0. Downloads always resume when possible. If you want to force a new download, use `force_download=True`.
  warnings.warn(
config.json: 100%|███████████████████████████████████████████████████████████████████████████████| 481/481 [00:00<00:00, 188kB/s]
D:\Anaconda\envs\pytorch\lib\site-packages\huggingface_hub\file_download.py:157: UserWarning: `huggingface_hub` cache-system uses symlinks by default to efficiently store duplicated files but your machine does not support them in C:\Users\18519\.cache\huggingface\hub\models--roberta-base. Caching files will still work but in a degraded version that might require more space on your disk. This warning can be disabled by setting the `HF_HUB_DISABLE_SYMLINKS_WARNING` environment variable. For more details, see https://huggingface.co/docs/huggingface_hub/how-to-cache#limitations.
To support symlinks on Windows, you either need to activate Developer Mode or to run Python as an administrator. In order to see activate developer mode, see this article: https://docs.microsoft.com/en-us/windows/apps/get-started/enable-your-device-for-development
  warnings.warn(message)
tokenizer_config.json: 100%|██████████████████████████████████████████████████████████████████| 25.0/25.0 [00:00<00:00, 10.0kB/s]
vocab.json: 100%|█████████████████████████████████████████████████████████████████████████████| 899k/899k [00:09<00:00, 99.5kB/s]
merges.txt: 100%|██████████████████████████████████████████████████████████████████████████████| 456k/456k [00:04<00:00, 108kB/s]
tokenizer.json: 100%|████████████████████████████████████████████████████████████████████████| 1.36M/1.36M [00:12<00:00, 105kB/s]
model.safetensors:   8%|█████▉                                                                | 41.9M/499M [04:32<44:47, 170kB/s]Traceback (most recent call last):
  File "D:\Anaconda\envs\pytorch\lib\site-packages\urllib3\response.py", line 748, in _error_catcher
    yield
  File "D:\Anaconda\envs\pytorch\lib\site-packages\urllib3\response.py", line 873, in _raw_read
    data = self._fp_read(amt, read1=read1) if not fp_closed else b""
  File "D:\Anaconda\envs\pytorch\lib\site-packages\urllib3\response.py", line 856, in _fp_read
    return self._fp.read(amt) if amt is not None else self._fp.read()
  File "D:\Anaconda\envs\pytorch\lib\http\client.py", line 459, in read
    n = self.readinto(b)
  File "D:\Anaconda\envs\pytorch\lib\http\client.py", line 503, in readinto
    n = self.fp.readinto(b)
  File "D:\Anaconda\envs\pytorch\lib\socket.py", line 669, in readinto
    return self._sock.recv_into(b)
  File "D:\Anaconda\envs\pytorch\lib\ssl.py", line 1274, in recv_into
    return self.read(nbytes, buffer)
  File "D:\Anaconda\envs\pytorch\lib\ssl.py", line 1132, in read
    return self._sslobj.read(len, buffer)
ConnectionResetError: [WinError 10054] 远程主机强迫关闭了一个现有的连接。

The above exception was the direct cause of the following exception:

Traceback (most recent call last):
  File "D:\Anaconda\envs\pytorch\lib\site-packages\requests\models.py", line 820, in generate
    yield from self.raw.stream(chunk_size, decode_content=True)
  File "D:\Anaconda\envs\pytorch\lib\site-packages\urllib3\response.py", line 1060, in stream
    data = self.read(amt=amt, decode_content=decode_content)
  File "D:\Anaconda\envs\pytorch\lib\site-packages\urllib3\response.py", line 949, in read
    data = self._raw_read(amt)
  File "D:\Anaconda\envs\pytorch\lib\site-packages\urllib3\response.py", line 902, in _raw_read
    self._fp.close()
  File "D:\Anaconda\envs\pytorch\lib\contextlib.py", line 131, in __exit__
    self.gen.throw(type, value, traceback)
  File "D:\Anaconda\envs\pytorch\lib\site-packages\urllib3\response.py", line 775, in _error_catcher
    raise ProtocolError(f"Connection broken: {e!r}", e) from e
urllib3.exceptions.ProtocolError: ("Connection broken: ConnectionResetError(10054, '远程主机强迫关闭了一个现有的连接。', None, 10054, None)", ConnectionResetError(10054, '远程主机强迫关闭了一个现有的连接。', None, 10054, None))

During handling of the above exception, another exception occurred:

Traceback (most recent call last):
  File "train.py", line 69, in <module>
    model = AutoModelForSequenceClassification.from_pretrained(model_args.model_name_or_path, config=config)
  File "D:\Anaconda\envs\pytorch\lib\site-packages\transformers\models\auto\auto_factory.py", line 563, in from_pretrained
    return model_class.from_pretrained(
  File "D:\Anaconda\envs\pytorch\lib\site-packages\transformers\modeling_utils.py", line 3306, in from_pretrained
    resolved_archive_file = cached_file(pretrained_model_name_or_path, filename, **cached_file_kwargs)
  File "D:\Anaconda\envs\pytorch\lib\site-packages\transformers\utils\hub.py", line 398, in cached_file
    resolved_file = hf_hub_download(
  File "D:\Anaconda\envs\pytorch\lib\site-packages\huggingface_hub\utils\_validators.py", line 114, in _inner_fn
    return fn(*args, **kwargs)
  File "D:\Anaconda\envs\pytorch\lib\site-packages\huggingface_hub\file_download.py", line 1221, in hf_hub_download
    return _hf_hub_download_to_cache_dir(
  File "D:\Anaconda\envs\pytorch\lib\site-packages\huggingface_hub\file_download.py", line 1367, in _hf_hub_download_to_cache_dir
    _download_to_tmp_and_move(
  File "D:\Anaconda\envs\pytorch\lib\site-packages\huggingface_hub\file_download.py", line 1884, in _download_to_tmp_and_move
    http_get(
  File "D:\Anaconda\envs\pytorch\lib\site-packages\huggingface_hub\file_download.py", line 539, in http_get
    for chunk in r.iter_content(chunk_size=DOWNLOAD_CHUNK_SIZE):
  File "D:\Anaconda\envs\pytorch\lib\site-packages\requests\models.py", line 822, in generate
    raise ChunkedEncodingError(e)
requests.exceptions.ChunkedEncodingError: ("Connection broken: ConnectionResetError(10054, '远程主机强迫关闭了一个现有的连接。', None, 10054, None)", ConnectionResetError(10054, '远程主机强迫关闭了一个现有的连接。', None, 10054, None))
Traceback (most recent call last):
  File "D:\Anaconda\envs\pytorch\lib\site-packages\urllib3\response.py", line 748, in _error_catcher
    yield
  File "D:\Anaconda\envs\pytorch\lib\site-packages\urllib3\response.py", line 873, in _raw_read
    data = self._fp_read(amt, read1=read1) if not fp_closed else b""
  File "D:\Anaconda\envs\pytorch\lib\site-packages\urllib3\response.py", line 856, in _fp_read
    return self._fp.read(amt) if amt is not None else self._fp.read()
  File "D:\Anaconda\envs\pytorch\lib\http\client.py", line 459, in read
    n = self.readinto(b)
  File "D:\Anaconda\envs\pytorch\lib\http\client.py", line 503, in readinto
    n = self.fp.readinto(b)
  File "D:\Anaconda\envs\pytorch\lib\socket.py", line 669, in readinto
    return self._sock.recv_into(b)
  File "D:\Anaconda\envs\pytorch\lib\ssl.py", line 1274, in recv_into
    return self.read(nbytes, buffer)
  File "D:\Anaconda\envs\pytorch\lib\ssl.py", line 1132, in read
    return self._sslobj.read(len, buffer)
ConnectionResetError: [WinError 10054] 远程主机强迫关闭了一个现有的连接。

The above exception was the direct cause of the following exception:

Traceback (most recent call last):
  File "D:\Anaconda\envs\pytorch\lib\site-packages\requests\models.py", line 820, in generate
    yield from self.raw.stream(chunk_size, decode_content=True)
  File "D:\Anaconda\envs\pytorch\lib\site-packages\urllib3\response.py", line 1060, in stream
    data = self.read(amt=amt, decode_content=decode_content)
  File "D:\Anaconda\envs\pytorch\lib\site-packages\urllib3\response.py", line 949, in read
    data = self._raw_read(amt)
  File "D:\Anaconda\envs\pytorch\lib\site-packages\urllib3\response.py", line 902, in _raw_read
    self._fp.close()
  File "D:\Anaconda\envs\pytorch\lib\contextlib.py", line 131, in __exit__
    self.gen.throw(type, value, traceback)
  File "D:\Anaconda\envs\pytorch\lib\site-packages\urllib3\response.py", line 775, in _error_catcher
    raise ProtocolError(f"Connection broken: {e!r}", e) from e
urllib3.exceptions.ProtocolError: ("Connection broken: ConnectionResetError(10054, '远程主机强迫关闭了一个现有的连接。', None, 10054, None)", ConnectionResetError(10054, '远程主机强迫关闭了一个现有的连接。', None, 10054, None))

During handling of the above exception, another exception occurred:

Traceback (most recent call last):
  File "train.py", line 69, in <module>
    model = AutoModelForSequenceClassification.from_pretrained(model_args.model_name_or_path, config=config)
  File "D:\Anaconda\envs\pytorch\lib\site-packages\transformers\models\auto\auto_factory.py", line 563, in from_pretrained
    return model_class.from_pretrained(
  File "D:\Anaconda\envs\pytorch\lib\site-packages\transformers\modeling_utils.py", line 3306, in from_pretrained
    resolved_archive_file = cached_file(pretrained_model_name_or_path, filename, **cached_file_kwargs)
  File "D:\Anaconda\envs\pytorch\lib\site-packages\transformers\utils\hub.py", line 398, in cached_file
    resolved_file = hf_hub_download(
  File "D:\Anaconda\envs\pytorch\lib\site-packages\huggingface_hub\utils\_validators.py", line 114, in _inner_fn
    return fn(*args, **kwargs)
  File "D:\Anaconda\envs\pytorch\lib\site-packages\huggingface_hub\file_download.py", line 1221, in hf_hub_download
    return _hf_hub_download_to_cache_dir(
  File "D:\Anaconda\envs\pytorch\lib\site-packages\huggingface_hub\file_download.py", line 1367, in _hf_hub_download_to_cache_dir
    _download_to_tmp_and_move(
  File "D:\Anaconda\envs\pytorch\lib\site-packages\huggingface_hub\file_download.py", line 1884, in _download_to_tmp_and_move
    http_get(
  File "D:\Anaconda\envs\pytorch\lib\site-packages\huggingface_hub\file_download.py", line 539, in http_get
    for chunk in r.iter_content(chunk_size=DOWNLOAD_CHUNK_SIZE):
  File "D:\Anaconda\envs\pytorch\lib\site-packages\requests\models.py", line 822, in generate
    raise ChunkedEncodingError(e)
requests.exceptions.ChunkedEncodingError: ("Connection broken: ConnectionResetError(10054, '远程主机强迫关闭了一个现有的连接。', None, 10054, None)", ConnectionResetError(10054, '远程主机强迫关闭了一个现有的连接。', None, 10054, None))
